{"uid":"5736a11e2dc30137","name":"test_NAF_17_2_0_verify_challenge_information_display","fullName":"tests.android.test_17_Challenge.TestNotification#test_NAF_17_2_0_verify_challenge_information_display","historyId":"ab02b76f1f67181e5c063f3fa6d35704","time":{"start":1760958926808,"stop":1760958926808,"duration":0},"description":"\n    Test Case: NAF-414\n    As a user I want to be able to view challenge details\n    Scenario: Challenge Information Display\n    \n    Steps:\n    1. Open the app, assume the user is logged in   \n    2. Go to \"Challenges\" tab\n    3. Verify challenge information is displayed\n    ","descriptionHtml":"<pre><code>Test Case: NAF-414\nAs a user I want to be able to view challenge details\nScenario: Challenge Information Display\n\nSteps:\n1. Open the app, assume the user is logged in   \n2. Go to &quot;Challenges&quot; tab\n3. Verify challenge information is displayed\n</code></pre>\n","status":"broken","statusMessage":"urllib3.exceptions.MaxRetryError: HTTPConnectionPool(host='127.0.0.1', port=4722): Max retries exceeded with url: /session (Caused by NewConnectionError('<urllib3.connection.HTTPConnection object at 0x104365ed0>: Failed to establish a new connection: [Errno 61] Connection refused'))","statusTrace":"../../../../anaconda3/lib/python3.11/site-packages/urllib3/connection.py:198: in _new_conn\n    sock = connection.create_connection(\n../../../../anaconda3/lib/python3.11/site-packages/urllib3/util/connection.py:85: in create_connection\n    raise err\n../../../../anaconda3/lib/python3.11/site-packages/urllib3/util/connection.py:73: in create_connection\n    sock.connect(sa)\nE   ConnectionRefusedError: [Errno 61] Connection refused\n\nThe above exception was the direct cause of the following exception:\n../../../../anaconda3/lib/python3.11/site-packages/urllib3/connectionpool.py:787: in urlopen\n    response = self._make_request(\n../../../../anaconda3/lib/python3.11/site-packages/urllib3/connectionpool.py:493: in _make_request\n    conn.request(\n../../../../anaconda3/lib/python3.11/site-packages/urllib3/connection.py:494: in request\n    self.endheaders()\n../../../../anaconda3/lib/python3.11/http/client.py:1281: in endheaders\n    self._send_output(message_body, encode_chunked=encode_chunked)\n../../../../anaconda3/lib/python3.11/http/client.py:1041: in _send_output\n    self.send(msg)\n../../../../anaconda3/lib/python3.11/http/client.py:979: in send\n    self.connect()\n../../../../anaconda3/lib/python3.11/site-packages/urllib3/connection.py:325: in connect\n    self.sock = self._new_conn()\n../../../../anaconda3/lib/python3.11/site-packages/urllib3/connection.py:213: in _new_conn\n    raise NewConnectionError(\nE   urllib3.exceptions.NewConnectionError: <urllib3.connection.HTTPConnection object at 0x104365ed0>: Failed to establish a new connection: [Errno 61] Connection refused\n\nThe above exception was the direct cause of the following exception:\ntests/android/test_17_Challenge.py:18: in setup_and_teardown\n    driver = DriverManagerAndroid.get_driver()\ncore/driver_manager_android.py:20: in get_driver\n    cls._driver = cls._create_driver()\ncore/driver_manager_android.py:51: in _create_driver\n    driver = webdriver.Remote(Config.APPIUM_SERVER_URL_ANDROID  , options=options)\n../../../../anaconda3/lib/python3.11/site-packages/appium/webdriver/webdriver.py:249: in __init__\n    super().__init__(\n../../../../anaconda3/lib/python3.11/site-packages/selenium/webdriver/remote/webdriver.py:263: in __init__\n    self.start_session(capabilities)\n../../../../anaconda3/lib/python3.11/site-packages/appium/webdriver/webdriver.py:342: in start_session\n    response = self.execute(RemoteCommand.NEW_SESSION, w3c_caps)\n../../../../anaconda3/lib/python3.11/site-packages/selenium/webdriver/remote/webdriver.py:455: in execute\n    response = cast(RemoteConnection, self.command_executor).execute(driver_command, params)\n../../../../anaconda3/lib/python3.11/site-packages/selenium/webdriver/remote/remote_connection.py:405: in execute\n    return self._request(command_info[0], url, body=data)\n../../../../anaconda3/lib/python3.11/site-packages/selenium/webdriver/remote/remote_connection.py:429: in _request\n    response = self._conn.request(method, url, body=body, headers=headers, timeout=self._client_config.timeout)\n../../../../anaconda3/lib/python3.11/site-packages/urllib3/_request_methods.py:143: in request\n    return self.request_encode_body(\n../../../../anaconda3/lib/python3.11/site-packages/urllib3/_request_methods.py:278: in request_encode_body\n    return self.urlopen(method, url, **extra_kw)\n../../../../anaconda3/lib/python3.11/site-packages/urllib3/poolmanager.py:459: in urlopen\n    response = conn.urlopen(method, u.request_uri, **kw)\n../../../../anaconda3/lib/python3.11/site-packages/urllib3/connectionpool.py:871: in urlopen\n    return self.urlopen(\n../../../../anaconda3/lib/python3.11/site-packages/urllib3/connectionpool.py:871: in urlopen\n    return self.urlopen(\n../../../../anaconda3/lib/python3.11/site-packages/urllib3/connectionpool.py:871: in urlopen\n    return self.urlopen(\n../../../../anaconda3/lib/python3.11/site-packages/urllib3/connectionpool.py:841: in urlopen\n    retries = retries.increment(\n../../../../anaconda3/lib/python3.11/site-packages/urllib3/util/retry.py:519: in increment\n    raise MaxRetryError(_pool, url, reason) from reason  # type: ignore[arg-type]\nE   urllib3.exceptions.MaxRetryError: HTTPConnectionPool(host='127.0.0.1', port=4722): Max retries exceeded with url: /session (Caused by NewConnectionError('<urllib3.connection.HTTPConnection object at 0x104365ed0>: Failed to establish a new connection: [Errno 61] Connection refused'))","flaky":false,"newFailed":false,"newBroken":false,"newPassed":false,"retriesCount":2,"retriesStatusChange":false,"beforeStages":[{"name":"delete_output_dir","time":{"start":1760956482571,"stop":1760956482571,"duration":0},"status":"passed","steps":[],"attachments":[],"parameters":[],"stepsCount":0,"hasContent":false,"attachmentStep":false,"shouldDisplayMessage":false,"attachmentsCount":0},{"name":"base_url","time":{"start":1760956482571,"stop":1760956482571,"duration":0},"status":"passed","steps":[],"attachments":[],"parameters":[],"stepsCount":0,"hasContent":false,"attachmentStep":false,"shouldDisplayMessage":false,"attachmentsCount":0},{"name":"setup_test_session","time":{"start":1760956482571,"stop":1760956482578,"duration":7},"status":"passed","steps":[],"attachments":[],"parameters":[],"stepsCount":0,"hasContent":false,"attachmentStep":false,"shouldDisplayMessage":false,"attachmentsCount":0},{"name":"pytestconfig","time":{"start":1760956482571,"stop":1760956482571,"duration":0},"status":"passed","steps":[],"attachments":[],"parameters":[],"stepsCount":0,"hasContent":false,"attachmentStep":false,"shouldDisplayMessage":false,"attachmentsCount":0},{"name":"_verify_url","time":{"start":1760956482571,"stop":1760956482571,"duration":0},"status":"passed","steps":[],"attachments":[],"parameters":[],"stepsCount":0,"hasContent":false,"attachmentStep":false,"shouldDisplayMessage":false,"attachmentsCount":0},{"name":"setup_and_teardown_test","time":{"start":1760958926808,"stop":1760958926809,"duration":1},"status":"passed","steps":[],"attachments":[],"parameters":[],"stepsCount":0,"hasContent":false,"attachmentStep":false,"shouldDisplayMessage":false,"attachmentsCount":0},{"name":"setup_and_teardown","time":{"start":1760958926809,"stop":1760958926812,"duration":3},"status":"broken","statusMessage":"urllib3.exceptions.MaxRetryError: HTTPConnectionPool(host='127.0.0.1', port=4722): Max retries exceeded with url: /session (Caused by NewConnectionError('<urllib3.connection.HTTPConnection object at 0x104365ed0>: Failed to establish a new connection: [Errno 61] Connection refused'))\n","statusTrace":"  File \"/Users/qingqinfang/anaconda3/lib/python3.11/site-packages/pluggy/_callers.py\", line 39, in _multicall\n    res = hook_impl.function(*args)\n          ^^^^^^^^^^^^^^^^^^^^^^^^^\n  File \"/Users/qingqinfang/anaconda3/lib/python3.11/site-packages/_pytest/fixtures.py\", line 1123, in pytest_fixture_setup\n    result = call_fixture_func(fixturefunc, request, kwargs)\n             ^^^^^^^^^^^^^^^^^^^^^^^^^^^^^^^^^^^^^^^^^^^^^^^\n  File \"/Users/qingqinfang/anaconda3/lib/python3.11/site-packages/_pytest/fixtures.py\", line 895, in call_fixture_func\n    fixture_result = next(generator)\n                     ^^^^^^^^^^^^^^^\n  File \"/Users/qingqinfang/Desktop/topfight/NancyAndersonFit/natal_mobile_auto/tests/android/test_17_Challenge.py\", line 18, in setup_and_teardown\n    driver = DriverManagerAndroid.get_driver()\n             ^^^^^^^^^^^^^^^^^^^^^^^^^^^^^^^^^\n  File \"/Users/qingqinfang/Desktop/topfight/NancyAndersonFit/natal_mobile_auto/core/driver_manager_android.py\", line 20, in get_driver\n    cls._driver = cls._create_driver()\n                  ^^^^^^^^^^^^^^^^^^^^\n  File \"/Users/qingqinfang/Desktop/topfight/NancyAndersonFit/natal_mobile_auto/core/driver_manager_android.py\", line 51, in _create_driver\n    driver = webdriver.Remote(Config.APPIUM_SERVER_URL_ANDROID  , options=options)\n             ^^^^^^^^^^^^^^^^^^^^^^^^^^^^^^^^^^^^^^^^^^^^^^^^^^^^^^^^^^^^^^^^^^^^^\n  File \"/Users/qingqinfang/anaconda3/lib/python3.11/site-packages/appium/webdriver/webdriver.py\", line 249, in __init__\n    super().__init__(\n  File \"/Users/qingqinfang/anaconda3/lib/python3.11/site-packages/selenium/webdriver/remote/webdriver.py\", line 263, in __init__\n    self.start_session(capabilities)\n  File \"/Users/qingqinfang/anaconda3/lib/python3.11/site-packages/appium/webdriver/webdriver.py\", line 342, in start_session\n    response = self.execute(RemoteCommand.NEW_SESSION, w3c_caps)\n               ^^^^^^^^^^^^^^^^^^^^^^^^^^^^^^^^^^^^^^^^^^^^^^^^^\n  File \"/Users/qingqinfang/anaconda3/lib/python3.11/site-packages/selenium/webdriver/remote/webdriver.py\", line 455, in execute\n    response = cast(RemoteConnection, self.command_executor).execute(driver_command, params)\n               ^^^^^^^^^^^^^^^^^^^^^^^^^^^^^^^^^^^^^^^^^^^^^^^^^^^^^^^^^^^^^^^^^^^^^^^^^^^^^\n  File \"/Users/qingqinfang/anaconda3/lib/python3.11/site-packages/selenium/webdriver/remote/remote_connection.py\", line 405, in execute\n    return self._request(command_info[0], url, body=data)\n           ^^^^^^^^^^^^^^^^^^^^^^^^^^^^^^^^^^^^^^^^^^^^^^\n  File \"/Users/qingqinfang/anaconda3/lib/python3.11/site-packages/selenium/webdriver/remote/remote_connection.py\", line 429, in _request\n    response = self._conn.request(method, url, body=body, headers=headers, timeout=self._client_config.timeout)\n               ^^^^^^^^^^^^^^^^^^^^^^^^^^^^^^^^^^^^^^^^^^^^^^^^^^^^^^^^^^^^^^^^^^^^^^^^^^^^^^^^^^^^^^^^^^^^^^^^\n  File \"/Users/qingqinfang/anaconda3/lib/python3.11/site-packages/urllib3/_request_methods.py\", line 143, in request\n    return self.request_encode_body(\n           ^^^^^^^^^^^^^^^^^^^^^^^^^\n  File \"/Users/qingqinfang/anaconda3/lib/python3.11/site-packages/urllib3/_request_methods.py\", line 278, in request_encode_body\n    return self.urlopen(method, url, **extra_kw)\n           ^^^^^^^^^^^^^^^^^^^^^^^^^^^^^^^^^^^^^\n  File \"/Users/qingqinfang/anaconda3/lib/python3.11/site-packages/urllib3/poolmanager.py\", line 459, in urlopen\n    response = conn.urlopen(method, u.request_uri, **kw)\n               ^^^^^^^^^^^^^^^^^^^^^^^^^^^^^^^^^^^^^^^^^\n  File \"/Users/qingqinfang/anaconda3/lib/python3.11/site-packages/urllib3/connectionpool.py\", line 871, in urlopen\n    return self.urlopen(\n           ^^^^^^^^^^^^^\n  File \"/Users/qingqinfang/anaconda3/lib/python3.11/site-packages/urllib3/connectionpool.py\", line 871, in urlopen\n    return self.urlopen(\n           ^^^^^^^^^^^^^\n  File \"/Users/qingqinfang/anaconda3/lib/python3.11/site-packages/urllib3/connectionpool.py\", line 871, in urlopen\n    return self.urlopen(\n           ^^^^^^^^^^^^^\n  File \"/Users/qingqinfang/anaconda3/lib/python3.11/site-packages/urllib3/connectionpool.py\", line 841, in urlopen\n    retries = retries.increment(\n              ^^^^^^^^^^^^^^^^^^\n  File \"/Users/qingqinfang/anaconda3/lib/python3.11/site-packages/urllib3/util/retry.py\", line 519, in increment\n    raise MaxRetryError(_pool, url, reason) from reason  # type: ignore[arg-type]\n    ^^^^^^^^^^^^^^^^^^^^^^^^^^^^^^^^^^^^^^^^^^^^^^^^^^^\n","steps":[],"attachments":[],"parameters":[],"stepsCount":0,"hasContent":true,"attachmentStep":false,"shouldDisplayMessage":true,"attachmentsCount":0}],"testStage":{"description":"\n    Test Case: NAF-414\n    As a user I want to be able to view challenge details\n    Scenario: Challenge Information Display\n    \n    Steps:\n    1. Open the app, assume the user is logged in   \n    2. Go to \"Challenges\" tab\n    3. Verify challenge information is displayed\n    ","status":"broken","statusMessage":"urllib3.exceptions.MaxRetryError: HTTPConnectionPool(host='127.0.0.1', port=4722): Max retries exceeded with url: /session (Caused by NewConnectionError('<urllib3.connection.HTTPConnection object at 0x104365ed0>: Failed to establish a new connection: [Errno 61] Connection refused'))","statusTrace":"../../../../anaconda3/lib/python3.11/site-packages/urllib3/connection.py:198: in _new_conn\n    sock = connection.create_connection(\n../../../../anaconda3/lib/python3.11/site-packages/urllib3/util/connection.py:85: in create_connection\n    raise err\n../../../../anaconda3/lib/python3.11/site-packages/urllib3/util/connection.py:73: in create_connection\n    sock.connect(sa)\nE   ConnectionRefusedError: [Errno 61] Connection refused\n\nThe above exception was the direct cause of the following exception:\n../../../../anaconda3/lib/python3.11/site-packages/urllib3/connectionpool.py:787: in urlopen\n    response = self._make_request(\n../../../../anaconda3/lib/python3.11/site-packages/urllib3/connectionpool.py:493: in _make_request\n    conn.request(\n../../../../anaconda3/lib/python3.11/site-packages/urllib3/connection.py:494: in request\n    self.endheaders()\n../../../../anaconda3/lib/python3.11/http/client.py:1281: in endheaders\n    self._send_output(message_body, encode_chunked=encode_chunked)\n../../../../anaconda3/lib/python3.11/http/client.py:1041: in _send_output\n    self.send(msg)\n../../../../anaconda3/lib/python3.11/http/client.py:979: in send\n    self.connect()\n../../../../anaconda3/lib/python3.11/site-packages/urllib3/connection.py:325: in connect\n    self.sock = self._new_conn()\n../../../../anaconda3/lib/python3.11/site-packages/urllib3/connection.py:213: in _new_conn\n    raise NewConnectionError(\nE   urllib3.exceptions.NewConnectionError: <urllib3.connection.HTTPConnection object at 0x104365ed0>: Failed to establish a new connection: [Errno 61] Connection refused\n\nThe above exception was the direct cause of the following exception:\ntests/android/test_17_Challenge.py:18: in setup_and_teardown\n    driver = DriverManagerAndroid.get_driver()\ncore/driver_manager_android.py:20: in get_driver\n    cls._driver = cls._create_driver()\ncore/driver_manager_android.py:51: in _create_driver\n    driver = webdriver.Remote(Config.APPIUM_SERVER_URL_ANDROID  , options=options)\n../../../../anaconda3/lib/python3.11/site-packages/appium/webdriver/webdriver.py:249: in __init__\n    super().__init__(\n../../../../anaconda3/lib/python3.11/site-packages/selenium/webdriver/remote/webdriver.py:263: in __init__\n    self.start_session(capabilities)\n../../../../anaconda3/lib/python3.11/site-packages/appium/webdriver/webdriver.py:342: in start_session\n    response = self.execute(RemoteCommand.NEW_SESSION, w3c_caps)\n../../../../anaconda3/lib/python3.11/site-packages/selenium/webdriver/remote/webdriver.py:455: in execute\n    response = cast(RemoteConnection, self.command_executor).execute(driver_command, params)\n../../../../anaconda3/lib/python3.11/site-packages/selenium/webdriver/remote/remote_connection.py:405: in execute\n    return self._request(command_info[0], url, body=data)\n../../../../anaconda3/lib/python3.11/site-packages/selenium/webdriver/remote/remote_connection.py:429: in _request\n    response = self._conn.request(method, url, body=body, headers=headers, timeout=self._client_config.timeout)\n../../../../anaconda3/lib/python3.11/site-packages/urllib3/_request_methods.py:143: in request\n    return self.request_encode_body(\n../../../../anaconda3/lib/python3.11/site-packages/urllib3/_request_methods.py:278: in request_encode_body\n    return self.urlopen(method, url, **extra_kw)\n../../../../anaconda3/lib/python3.11/site-packages/urllib3/poolmanager.py:459: in urlopen\n    response = conn.urlopen(method, u.request_uri, **kw)\n../../../../anaconda3/lib/python3.11/site-packages/urllib3/connectionpool.py:871: in urlopen\n    return self.urlopen(\n../../../../anaconda3/lib/python3.11/site-packages/urllib3/connectionpool.py:871: in urlopen\n    return self.urlopen(\n../../../../anaconda3/lib/python3.11/site-packages/urllib3/connectionpool.py:871: in urlopen\n    return self.urlopen(\n../../../../anaconda3/lib/python3.11/site-packages/urllib3/connectionpool.py:841: in urlopen\n    retries = retries.increment(\n../../../../anaconda3/lib/python3.11/site-packages/urllib3/util/retry.py:519: in increment\n    raise MaxRetryError(_pool, url, reason) from reason  # type: ignore[arg-type]\nE   urllib3.exceptions.MaxRetryError: HTTPConnectionPool(host='127.0.0.1', port=4722): Max retries exceeded with url: /session (Caused by NewConnectionError('<urllib3.connection.HTTPConnection object at 0x104365ed0>: Failed to establish a new connection: [Errno 61] Connection refused'))","steps":[],"attachments":[{"uid":"401750e19b7098a8","name":"log","source":"401750e19b7098a8.txt","type":"text/plain","size":2969}],"parameters":[],"stepsCount":0,"hasContent":true,"attachmentStep":false,"shouldDisplayMessage":true,"attachmentsCount":1},"afterStages":[{"name":"setup_and_teardown_test::0","time":{"start":1760958926893,"stop":1760958926893,"duration":0},"status":"passed","steps":[],"attachments":[],"parameters":[],"stepsCount":0,"hasContent":false,"attachmentStep":false,"shouldDisplayMessage":false,"attachmentsCount":0},{"name":"setup_test_session::0","time":{"start":1760959053235,"stop":1760959053235,"duration":0},"status":"passed","steps":[],"attachments":[],"parameters":[],"stepsCount":0,"hasContent":false,"attachmentStep":false,"shouldDisplayMessage":false,"attachmentsCount":0}],"labels":[{"name":"severity","value":"blocker"},{"name":"feature","value":"17.0.0 Challenge"},{"name":"epic","value":"Mobile App Testing-Android"},{"name":"story","value":"17.2.0 Mob_As a user I want to be able to view challenge details"},{"name":"tag","value":"program"},{"name":"parentSuite","value":"tests.android"},{"name":"suite","value":"test_17_Challenge"},{"name":"subSuite","value":"TestNotification"},{"name":"host","value":"fqqqqq.local"},{"name":"thread","value":"99247-MainThread"},{"name":"framework","value":"pytest"},{"name":"language","value":"cpython3"},{"name":"package","value":"tests.android.test_17_Challenge"},{"name":"resultFormat","value":"allure2"}],"parameters":[],"links":[{"name":"Qase: NAF-414","url":"https://app.qase.io/case/NAF-414","type":"link"}],"hidden":false,"retry":false,"extra":{"severity":"blocker","retries":[{"uid":"e0836d564c66bd3a","status":"broken","statusDetails":"urllib3.exceptions.MaxRetryError: HTTPConnectionPool(host='127.0.0.1', port=4722): Max retries exceeded with url: /session (Caused by NewConnectionError('<urllib3.connection.HTTPConnection object at 0x103e9dd10>: Failed to establish a new connection: [Errno 61] Connection refused'))","time":{"start":1760958925688,"stop":1760958925688,"duration":0}},{"uid":"8f1a777eb40b802","status":"broken","statusDetails":"urllib3.exceptions.MaxRetryError: HTTPConnectionPool(host='127.0.0.1', port=4722): Max retries exceeded with url: /session (Caused by NewConnectionError('<urllib3.connection.HTTPConnection object at 0x104145d50>: Failed to establish a new connection: [Errno 61] Connection refused'))","time":{"start":1760958924615,"stop":1760958924615,"duration":0}}],"categories":[{"name":"Test defects","matchedStatuses":[]}],"tags":["program"]},"source":"5736a11e2dc30137.json","parameterValues":[]}